Workbook

Sheet Read Me
A1: HR Analytics Dashboard
A2: Built by Abdul Rehman — Senior HR Executive (1000+ hires)
A4: What this workbook does
A5: Turns raw hiring and headcount data into the three metrics every HR leader watches:
A6: 1. Hiring Funnel — where candidates drop off, and which stage leaks the most.
A7: 2. Time to Hire — how long hiring really takes, by department.
A8: 3. Turnover — monthly and annualized separation rates, plus tenure risk.
A10: How to use it
A11: 1. Replace the SAMPLE data on the 'Hiring Data' and 'Headcount' sheets with your own.
A12: Keep the column order and date format (YYYY-MM-DD). Leave a cell blank when a
A13: stage did not happen (e.g. no Offer Date for rejected candidates).
A14: 2. Everything else recalculates automatically — Funnel, Time to Hire, Turnover,
... A29: hires fast with higher churn; specialist roles take longer to fill.

Sheet Hiring Data
A1: Candidate ID | B1: Name | C1: Role | D1: Department | E1: Source | F1: Applied Date | G1: Screened Date | H1: Interview Date | I1: Offer Date | J1: Join Date | K1: Final Status | L1: Last Stage
A2: CAND-0001 | B2: Ahmed Mahmood | C2: Operations Executive | D2: Operations | E2: Rozee | F2: 46087 | G2: 46088 | K2: Rejected | L2: Screened
A3: CAND-0002 | B3: Zainab Khan | C3: Team Lead - Support | D3: Customer Support | E3: LinkedIn | F3: 46009 | G3: 46014 | H3: 46025 | I3: 46032 | J3: 46052 | K3: Hired | L3: Hired
A4: CAND-0003 | B4: Shahid Butt | C4: Senior CSR | D4: Customer Support | E4: LinkedIn | F4: 46043 | G4: 46046 | H4: 46052 | K4: Rejected | L4: Interviewed
A5: CAND-0004 | B5: Ayesha Raza | C5: Senior CSR | D5: Customer Support | E5: Rozee | F5: 46271 | G5: 46272 | K5: Rejected | L5: Screened
A6: CAND-0005 | B6: Rabia Butt | C6: HR Executive | D6: Human Resources | E6: Walk-in | F6: 46147 | G6: 46148 | H6: 46154 | K6: In Process | L6: Interviewed
A7: CAND-0006 | B7: Fahad Butt | C7: Customer Support Executive | D7: Customer Support | E7: Referral | F7: 46148 | G7: 46151 | H7: 46158 | K7: Rejected | L7: Interviewed
A8: CAND-0007 | B8: Tariq Malik | C8: Team Lead - Support | D8: Customer Support | E8: Walk-in | F8: 46087 | G8: 46091 | H8: 46102 | I8: 46106 | K8: Withdrawn | L8: Offered
A9: CAND-0008 | B9: Mahnoor Javed | C9: Operations Executive | D9: Operations | E9: LinkedIn | F9: 46123 | G9: 46124 | H9: 46136 | K9: Rejected | L9: Interviewed
A10: CAND-0009 | B10: Fahad Nawaz | C10: Quality Analyst | D10: Operations | E10: Referral | F10: 46035 | G10: 46037 | K10: Rejected | L10: Screened
A11: CAND-0010 | B11: Shahid Hussain | C11: Quality Analyst | D11: Operations | E11: Rozee | F11: 46074 | K11: Rejected | L11: Applied
A12: CAND-0011 | B12: Fatima Javed | C12: Software Engineer | D12: Information Technology | E12: LinkedIn | F12: 46040 | G12: 46044 | H12: 46053 | I12: 46058 | J12: 46082 | K12: Hired | L12: Hired
A13: CAND-0012 | B13: Kiran Ahmed | C13: Team Lead - Support | D13: Customer Support | E13: Walk-in | F13: 46098 | G13: 46101 | H13: 46110 | I13: 46112 | K13: Withdrawn | L13: Offered
A14: CAND-0013 | B14: Kamran Akhtar | C14: Quality Analyst | D14: Operations | E14: Indeed | F14: 46221 | K14: Rejected | L14: Applied
A15: CAND-0014 | B15: Kamran Qureshi | C15: Team Lead - Support | D15: Customer Support | E15: Indeed | F15: 46040 | G15: 46042 | H15: 46053 | K15: Rejected | L15: Interviewed
A16: CAND-0015 | B16: Ayesha Nawaz | C16: Software Engineer | D16: Information Technology | E16: Rozee | F16: 46119 | G16: 46121 | K16: In Process | L16: Screened
A17: CAND-0016 | B17: Sadia Javed | C17: Team Lead - Support | D17: Customer Support | E17: LinkedIn | F17: 46234 | G17: 46236 | K17: In Process | L17: Screened
A18: CAND-0017 | B18: Kamran Javed | C18: Senior CSR | D18: Customer Support | E18: Walk-in | F18: 46178 | K18: In Process | L18: Applied
A19: CAND-0018 | B19: Nabeel Butt | C19: Operations Executive | D19: Operations | E19: Referral | F19: 46153 | G19: 46158 | H19: 46164 | I19: 46168 | J19: 46192 | K19: Hired | L19: Hired
A20: CAND-0019 | B20: Mahnoor Khan | C20: Team Lead - Support | D20: Customer Support | E20: LinkedIn | F20: 45992 | G20: 45993 | K20: Rejected | L20: Screened
A21: CAND-0020 | B21: Asma Farooq | C21: Senior CSR | D21: Customer Support | E21: Indeed | F21: 46238 | G21: 46243 | H21: 46249 | K21: Rejected | L21: Interviewed
A22: CAND-0021 | B22: Ayesha Sheikh | C22: Customer Support Executive | D22: Customer Support | E22: Referral | F22: 46143 | G22: 46147 | K22: Rejected | L22: Screened
A23: CAND-0022 | B23: Fatima Hussain | C23: Operations Executive | D23: Operations | E23: Rozee | F23: 46017 | G23: 46019 | H23: 46024 | I23: 46028 | J23: 46037 | K23: Hired | L23: Hired
A24: CAND-0023 | B24: Fatima Sheikh | C24: Software Engineer | D24: Information Technology | E24: Walk-in | F24: 45969 | K24: In Process | L24: Applied
A25: CAND-0024 | B25: Zainab Farooq | C25: Customer Support Executive | D25: Customer Support | E25: Referral | F25: 46071 | K25: Rejected | L25: Applied
A26: CAND-0025 | B26: Ahmed Hussain | C26: Senior CSR | D26: Customer Support | E26: Rozee | F26: 46194 | G26: 46199 | K26: Rejected | L26: Screened
A27: CAND-0026 | B27: Ali Khan | C27: Senior CSR | D27: Customer Support | E27: Walk-in | F27: 46239 | G27: 46242 | H27: 46254 | I27: 46262 | J27: 46270 | K27: Hired | L27: Hired
A28: CAND-0027 | B28: Sana Ahmed | C28: Software Engineer | D28: Information Technology | E28: Walk-in | F28: 45996 | G28: 45998 | H28: 46010 | I28: 46016 | J28: 46025 | K28: Hired | L28: Hired
A29: CAND-0028 | B29: Hamza Shah | C29: IT Support Officer | D29: Information Technology | E29: Rozee | F29: 46084 | G29: 46086 | K29: Rejected | L29: Screened
A30: CAND-0029 | B30: Ahmed Farooq | C30: Customer Support Executive | D30: Customer Support | E30: Walk-in | F30: 46250 | K30: Rejected | L30: Applied
A31: CAND-0030 | B31: Hamza Malik | C31: Team Lead - Support | D31: Customer Support | E31: Rozee | F31: 45997 | K31: Rejected | L31: Applied
A32: CAND-0031 | B32: Rabia Mahmood | C32: Senior CSR | D32: Customer Support | E32: Rozee | F32: 46275 | K32: Rejected | L32: Applied
A33: CAND-0032 | B33: Asma Javed | C33: Software Engineer | D33: Information Technology | E33: Walk-in | F33: 46115 | K33: Rejected | L33: Applied
A34: CAND-0033 | B34: Ayesha Nawaz | C34: Senior CSR | D34: Customer Support | E34: LinkedIn | F34: 46245 | G34: 46248 | H34: 46256 | I34: 46263 | K34: Withdrawn | L34: Offered
A35: CAND-0034 | B35: Hamza Nawaz | C35: IT Support Officer | D35: Information Technology | E35: LinkedIn | F35: 46009 | G35: 46012 | H35: 46020 | K35: Rejected | L35: Interviewed
A36: CAND-0035 | B36: Kiran Farooq | C36: Customer Support Executive | D36: Customer Support | E36: Walk-in | F36: 46180 | G36: 46181 | H36: 46186 | I36: 46194 | J36: 46218 | K36: Hired | L36: Hired
A37: CAND-0036 | B37: Usman Khan | C37: Senior CSR | D37: Customer Support | E37: Rozee | F37: 46148 | K37: Rejected | L37: Applied
A38: CAND-0037 | B38: Ali Sheikh | C38: Senior CSR | D38: Customer Support | E38: Indeed | F38: 46014 | G38: 46019 | K38: Rejected | L38: Screened
A39: CAND-0038 | B39: Mahnoor Javed | C39: Operations Executive | D39: Operations | E39: Indeed | F39: 46052 | K39: Rejected | L39: Applied
A40: CAND-0039 | B40: Zainab Akhtar | C40: Quality Analyst | D40: Operations | E40: Indeed | F40: 46098 | G40: 46099 | H40: 46102 | K40: Rejected | L40: Interviewed
...

Sheet Headcount
A1: Month | B1: Department | C1: Opening HC | D1: Joiners | E1: Leavers | F1: Closing HC
A2: Oct-25 | B2: Customer Support | C2: 118 | D2: 5 | E2: 4 | F2: 119
A3: Oct-25 | B3: Human Resources | C3: 8 | D3: 2 | E3: 1 | F3: 9
A4: Oct-25 | B4: Information Technology | C4: 24 | D4: 2 | E4: 1 | F4: 25
A5: Oct-25 | B5: Finance | C5: 10 | D5: 0 | E5: 2 | F5: 8
A6: Oct-25 | B6: Operations | C6: 38 | D6: 0 | E6: 1 | F6: 37
A7: Nov-25 | B7: Customer Support | C7: 119 | D7: 5 | E7: 5 | F7: 119
A8: Nov-25 | B8: Human Resources | C8: 9 | D8: 0 | E8: 2 | F8: 7
A9: Nov-25 | B9: Information Technology | C9: 25 | D9: 0 | E9: 2 | F9: 23
A10: Nov-25 | B10: Finance | C10: 8 | D10: 0 | E10: 1 | F10: 7
A11: Nov-25 | B11: Operations | C11: 37 | D11: 0 | E11: 0 | F11: 37
A12: Dec-25 | B12: Customer Support | C12: 119 | D12: 2 | E12: 3 | F12: 118
A13: Dec-25 | B13: Human Resources | C13: 7 | D13: 1 | E13: 2 | F13: 6
... A61: Sep-26 | B61: Operations | C61: 33 | D61: 2 | E61: 0 | F61: 35

Sheet Funnel
A1: Stage | B1: Candidates | C1: % of Applied | D1: Conversion from Previous
A2: Applied | B2: =COUNTA('Hiring Data'!F2:F77) | C2: =IF($B$2=0,0,B2/$B$2) | D2: —
A3: Screened | B3: =SUM(COUNTIF('Hiring Data'!L2:L77,{"Screened","Interviewed","Offered","Hired"})) | C3: =IF($B$2=0,0,B3/$B$2) | D3: =IF(B2=0,0,B3/B2)
A4: Interviewed | B4: =SUM(COUNTIF('Hiring Data'!L2:L77,{"Interviewed","Offered","Hired"})) | C4: =IF($B$2=0,0,B4/$B$2) | D4: =IF(B3=0,0,B4/B3)
A5: Offered | B5: =SUM(COUNTIF('Hiring Data'!L2:L77,{"Offered","Hired"})) | C5: =IF($B$2=0,0,B5/$B$2) | D5: =IF(B4=0,0,B5/B4)
A6: Hired | B6: =COUNTIF('Hiring Data'!K2:K77,"Hired") | C6: =IF($B$2=0,0,B6/$B$2) | D6: =IF(B5=0,0,B6/B5)
A8: Biggest drop-off:
A9: =INDEX(A3:A6,MATCH(MIN(D3:D6),D3:D6,0)) & " stage (" & TEXT(MIN(D3:D6),"0.0%") & " conversion)"

Sheet Time to Hire
A1: Department | B1: Avg Days: Applied → Offer | C1: Avg Days: Offer → Join | D1: Avg Days: Applied → Join | E1: Hires
A2: Customer Support | B2: =IFERROR(AVERAGEIFS('Hiring Data'!I2:I77,'Hiring Data'!D2:D77,"Customer Support",'Hiring Data'!K2:K77,"Hired")-AVERAGEIFS('Hiring Data'!F2:F77,'Hiring Data'!D2:D77,"Customer Support",'Hiring Data'!K2:K77,"Hired"),"") | C2: =IFERROR(AVERAGEIFS('Hiring Data'!J2:J77,'Hiring Data'!D2:D77,"Customer Support",'Hiring Data'!K2:K77,"Hired")-AVERAGEIFS('Hiring Data'!I2:I77,'Hiring Data'!D2:D77,"Customer Support",'Hiring Data'!K2:K77,"Hired"),"") | D2: =IFERROR(B2+C2,"") | E2: =COUNTIFS('Hiring Data'!D2:D77,"Customer Support",'Hiring Data'!K2:K77,"Hired")
A3: Human Resources | B3: =IFERROR(AVERAGEIFS('Hiring Data'!I2:I77,'Hiring Data'!D2:D77,"Human Resources",'Hiring Data'!K2:K77,"Hired")-AVERAGEIFS('Hiring Data'!F2:F77,'Hiring Data'!D2:D77,"Human Resources",'Hiring Data'!K2:K77,"Hired"),"") | C3: =IFERROR(AVERAGEIFS('Hiring Data'!J2:J77,'Hiring Data'!D2:D77,"Human Resources",'Hiring Data'!K2:K77,"Hired")-AVERAGEIFS('Hiring Data'!I2:I77,'Hiring Data'!D2:D77,"Human Resources",'Hiring Data'!K2:K77,"Hired"),"") | D3: =IFERROR(B3+C3,"") | E3: =COUNTIFS('Hiring Data'!D2:D77,"Human Resources",'Hiring Data'!K2:K77,"Hired")
A4: Information Technology | B4: =IFERROR(AVERAGEIFS('Hiring Data'!I2:I77,'Hiring Data'!D2:D77,"Information Technology",'Hiring Data'!K2:K77,"Hired")-AVERAGEIFS('Hiring Data'!F2:F77,'Hiring Data'!D2:D77,"Information Technology",'Hiring Data'!K2:K77,"Hired"),"") | C4: =IFERROR(AVERAGEIFS('Hiring Data'!J2:J77,'Hiring Data'!D2:D77,"Information Technology",'Hiring Data'!K2:K77,"Hired")-AVERAGEIFS('Hiring Data'!I2:I77,'Hiring Data'!D2:D77,"Information Technology",'Hiring Data'!K2:K77,"Hired"),"") | D4: =IFERROR(B4+C4,"") | E4: =COUNTIFS('Hiring Data'!D2:D77,"Information Technology",'Hiring Data'!K2:K77,"Hired")
A5: Finance | B5: =IFERROR(AVERAGEIFS('Hiring Data'!I2:I77,'Hiring Data'!D2:D77,"Finance",'Hiring Data'!K2:K77,"Hired")-AVERAGEIFS('Hiring Data'!F2:F77,'Hiring Data'!D2:D77,"Finance",'Hiring Data'!K2:K77,"Hired"),"") | C5: =IFERROR(AVERAGEIFS('Hiring Data'!J2:J77,'Hiring Data'!D2:D77,"Finance",'Hiring Data'!K2:K77,"Hired")-AVERAGEIFS('Hiring Data'!I2:I77,'Hiring Data'!D2:D77,"Finance",'Hiring Data'!K2:K77,"Hired"),"") | D5: =IFERROR(B5+C5,"") | E5: =COUNTIFS('Hiring Data'!D2:D77,"Finance",'Hiring Data'!K2:K77,"Hired")
A6: Operations | B6: =IFERROR(AVERAGEIFS('Hiring Data'!I2:I77,'Hiring Data'!D2:D77,"Operations",'Hiring Data'!K2:K77,"Hired")-AVERAGEIFS('Hiring Data'!F2:F77,'Hiring Data'!D2:D77,"Operations",'Hiring Data'!K2:K77,"Hired"),"") | C6: =IFERROR(AVERAGEIFS('Hiring Data'!J2:J77,'Hiring Data'!D2:D77,"Operations",'Hiring Data'!K2:K77,"Hired")-AVERAGEIFS('Hiring Data'!I2:I77,'Hiring Data'!D2:D77,"Operations",'Hiring Data'!K2:K77,"Hired"),"") | D6: =IFERROR(B6+C6,"") | E6: =COUNTIFS('Hiring Data'!D2:D77,"Operations",'Hiring Data'!K2:K77,"Hired")
A7: Company Average | B7: =AVERAGE(B2:B6) | C7: =AVERAGE(C2:C6) | D7: =AVERAGE(D2:D6) | E7: =SUM(E2:E6)

Sheet Turnover
A1: Month | B1: Avg Headcount | C1: Separations | D1: Monthly Turnover % | E1: Annualized Turnover %
A2: Oct-25 | B2: =(SUMIFS(Headcount!C2:C62,Headcount!A2:A62,"Oct-25")+SUMIFS(Headcount!F2:F62,Headcount!A2:A62,"Oct-25"))/2 | C2: =SUMIFS(Headcount!E2:E62,Headcount!A2:A62,"Oct-25") | D2: =IF(B2=0,0,C2/B2) | E2: =D2*12
A3: Nov-25 | B3: =(SUMIFS(Headcount!C2:C62,Headcount!A2:A62,"Nov-25")+SUMIFS(Headcount!F2:F62,Headcount!A2:A62,"Nov-25"))/2 | C3: =SUMIFS(Headcount!E2:E62,Headcount!A2:A62,"Nov-25") | D3: =IF(B3=0,0,C3/B3) | E3: =D3*12
A4: Dec-25 | B4: =(SUMIFS(Headcount!C2:C62,Headcount!A2:A62,"Dec-25")+SUMIFS(Headcount!F2:F62,Headcount!A2:A62,"Dec-25"))/2 | C4: =SUMIFS(Headcount!E2:E62,Headcount!A2:A62,"Dec-25") | D4: =IF(B4=0,0,C4/B4) | E4: =D4*12
A5: Jan-26 | B5: =(SUMIFS(Headcount!C2:C62,Headcount!A2:A62,"Jan-26")+SUMIFS(Headcount!F2:F62,Headcount!A2:A62,"Jan-26"))/2 | C5: =SUMIFS(Headcount!E2:E62,Headcount!A2:A62,"Jan-26") | D5: =IF(B5=0,0,C5/B5) | E5: =D5*12
A6: Feb-26 | B6: =(SUMIFS(Headcount!C2:C62,Headcount!A2:A62,"Feb-26")+SUMIFS(Headcount!F2:F62,Headcount!A2:A62,"Feb-26"))/2 | C6: =SUMIFS(Headcount!E2:E62,Headcount!A2:A62,"Feb-26") | D6: =IF(B6=0,0,C6/B6) | E6: =D6*12
A7: Mar-26 | B7: =(SUMIFS(Headcount!C2:C62,Headcount!A2:A62,"Mar-26")+SUMIFS(Headcount!F2:F62,Headcount!A2:A62,"Mar-26"))/2 | C7: =SUMIFS(Headcount!E2:E62,Headcount!A2:A62,"Mar-26") | D7: =IF(B7=0,0,C7/B7) | E7: =D7*12
A8: Apr-26 | B8: =(SUMIFS(Headcount!C2:C62,Headcount!A2:A62,"Apr-26")+SUMIFS(Headcount!F2:F62,Headcount!A2:A62,"Apr-26"))/2 | C8: =SUMIFS(Headcount!E2:E62,Headcount!A2:A62,"Apr-26") | D8: =IF(B8=0,0,C8/B8) | E8: =D8*12
A9: May-26 | B9: =(SUMIFS(Headcount!C2:C62,Headcount!A2:A62,"May-26")+SUMIFS(Headcount!F2:F62,Headcount!A2:A62,"May-26"))/2 | C9: =SUMIFS(Headcount!E2:E62,Headcount!A2:A62,"May-26") | D9: =IF(B9=0,0,C9/B9) | E9: =D9*12
A10: Jun-26 | B10: =(SUMIFS(Headcount!C2:C62,Headcount!A2:A62,"Jun-26")+SUMIFS(Headcount!F2:F62,Headcount!A2:A62,"Jun-26"))/2 | C10: =SUMIFS(Headcount!E2:E62,Headcount!A2:A62,"Jun-26") | D10: =IF(B10=0,0,C10/B10) | E10: =D10*12
A11: Jul-26 | B11: =(SUMIFS(Headcount!C2:C62,Headcount!A2:A62,"Jul-26")+SUMIFS(Headcount!F2:F62,Headcount!A2:A62,"Jul-26"))/2 | C11: =SUMIFS(Headcount!E2:E62,Headcount!A2:A62,"Jul-26") | D11: =IF(B11=0,0,C11/B11) | E11: =D11*12
A12: Aug-26 | B12: =(SUMIFS(Headcount!C2:C62,Headcount!A2:A62,"Aug-26")+SUMIFS(Headcount!F2:F62,Headcount!A2:A62,"Aug-26"))/2 | C12: =SUMIFS(Headcount!E2:E62,Headcount!A2:A62,"Aug-26") | D12: =IF(B12=0,0,C12/B12) | E12: =D12*12
A13: Sep-26 | B13: =(SUMIFS(Headcount!C2:C62,Headcount!A2:A62,"Sep-26")+SUMIFS(Headcount!F2:F62,Headcount!A2:A62,"Sep-26"))/2 | C13: =SUMIFS(Headcount!E2:E62,Headcount!A2:A62,"Sep-26") | D13: =IF(B13=0,0,C13/B13) | E13: =D13*12
A14: 12-Month Average | D14: =AVERAGE(D2:D13) | E14: =AVERAGE(E2:E13)
A16: Annualized Turnover by Department
A17: Department | B17: Avg Headcount | C17: Separations (12m) | D17: Annual Turnover %
A18: Customer Support | B18: =(SUMIFS(Headcount!C2:C62,Headcount!B2:B62,"Customer Support")+SUMIFS(Headcount!F2:F62,Headcount!B2:B62,"Customer Support"))/2 | C18: =SUMIFS(Headcount!E2:E62,Headcount!B2:B62,"Customer Support") | D18: =IF(B18=0,0,C18/B18)
A19: Human Resources | B19: =(SUMIFS(Headcount!C2:C62,Headcount!B2:B62,"Human Resources")+SUMIFS(Headcount!F2:F62,Headcount!B2:B62,"Human Resources"))/2 | C19: =SUMIFS(Headcount!E2:E62,Headcount!B2:B62,"Human Resources") | D19: =IF(B19=0,0,C19/B19)
A20: Information Technology | B20: =(SUMIFS(Headcount!C2:C62,Headcount!B2:B62,"Information Technology")+SUMIFS(Headcount!F2:F62,Headcount!B2:B62,"Information Technology"))/2 | C20: =SUMIFS(Headcount!E2:E62,Headcount!B2:B62,"Information Technology") | D20: =IF(B20=0,0,C20/B20)
A21: Finance | B21: =(SUMIFS(Headcount!C2:C62,Headcount!B2:B62,"Finance")+SUMIFS(Headcount!F2:F62,Headcount!B2:B62,"Finance"))/2 | C21: =SUMIFS(Headcount!E2:E62,Headcount!B2:B62,"Finance") | D21: =IF(B21=0,0,C21/B21)
A22: Operations | B22: =(SUMIFS(Headcount!C2:C62,Headcount!B2:B62,"Operations")+SUMIFS(Headcount!F2:F62,Headcount!B2:B62,"Operations"))/2 | C22: =SUMIFS(Headcount!E2:E62,Headcount!B2:B62,"Operations") | D22: =IF(B22=0,0,C22/B22)

Sheet Dashboard
A1: HR Analytics Dashboard
A2: Oct 2025 – Sep 2026 • Sample data — replace with your own on Hiring Data / Headcount
A4: Total Hires (12m)
A5: =COUNTIF('Hiring Data'!K2:K77,"Hired")
A6: Avg Time to Hire (days)
A7: ='Time to Hire'!D7
A8: Avg Monthly Turnover
A9: =AVERAGE(Turnover!D2:D13)
A10: Offer Acceptance Rate
A11: =IFERROR(COUNTIF('Hiring Data'!K2:K77,"Hired")/COUNTIF('Hiring Data'!L2:L77,"Offered")+COUNTIF('Hiring Data'!L2:L77,"Hired"),0)
